<?xml version="1.0"?>
<robot name="kuka_iiwa">
  <link name="base_link">
    <visual>
      <geometry>
        <cylinder length="0.15" radius="0.1"/>
      </geometry>
      <material name="grey">
        <color rgba="0.5 0.5 0.5 1"/>
      </material>
    </visual>
    <collision>
      <geometry>
        <cylinder length="0.15" radius="0.1"/>
      </geometry>
    </collision>
    <inertial>
      <mass value="5"/>
      <inertia ixx="0.1" ixy="0" ixz="0" iyy="0.1" iyz="0" izz="0.1"/>
    </inertial>
  </link>

  <link name="link_1">
    <visual>
      <geometry>
        <cylinder length="0.2" radius="0.06"/>
      </geometry>
      <material name="orange">
        <color rgba="1 0.5 0 1"/>
      </material>
    </visual>
    <collision>
      <geometry>
        <cylinder length="0.2" radius="0.06"/>
      </geometry>
    </collision>
    <inertial>
      <mass value="2"/>
      <inertia ixx="0.05" ixy="0" ixz="0" iyy="0.05" iyz="0" izz="0.05"/>
    </inertial>
  </link>

  <joint name="joint_1" type="revolute">
    <parent link="base_link"/>
    <child link="link_1"/>
    <origin xyz="0 0 0.1" rpy="0 0 0"/>
    <axis xyz="0 0 1"/>
    <limit lower="-2.97" upper="2.97" effort="150" velocity="1.7"/>
  </joint>

  <link name="link_2">
    <visual>
      <geometry>
        <cylinder length="0.2" radius="0.06"/>
      </geometry>
      <material name="orange">
        <color rgba="1 0.5 0 1"/>
      </material>
    </visual>
    <collision>
      <geometry>
        <cylinder length="0.2" radius="0.06"/>
      </geometry>
    </collision>
    <inertial>
      <mass value="2"/>
      <inertia ixx="0.05" ixy="0" ixz="0" iyy="0.05" iyz="0" izz="0.05"/>
    </inertial>
  </link>

  <joint name="joint_2" type="revolute">
    <parent link="link_1"/>
    <child link="link_2"/>
    <origin xyz="0 0 0.2" rpy="1.57 0 0"/>
    <axis xyz="0 0 1"/>
    <limit lower="-2.09" upper="2.09" effort="150" velocity="1.7"/>
  </joint>

  <link name="link_3">
    <visual>
      <geometry>
        <cylinder length="0.2" radius="0.06"/>
      </geometry>
      <material name="orange">
        <color rgba="1 0.5 0 1"/>
      </material>
    </visual>
    <collision>
      <geometry>
        <cylinder length="0.2" radius="0.06"/>
      </geometry>
    </collision>
    <inertial>
      <mass value="2"/>
      <inertia ixx="0.05" ixy="0" ixz="0" iyy="0.05" iyz="0" izz="0.05"/>
    </inertial>
  </link>

  <joint name="joint_3" type="revolute">
    <parent link="link_2"/>
    <child link="link_3"/>
    <origin xyz="0 0 0.2" rpy="-1.57 0 0"/>
    <axis xyz="0 0 1"/>
    <limit lower="-2.97" upper="2.97" effort="150" velocity="1.7"/>
  </joint>

  <link name="link_4">
    <visual>
      <geometry>
        <cylinder length="0.2" radius="0.06"/>
      </geometry>
      <material name="orange">
        <color rgba="1 0.5 0 1"/>
      </material>
    </visual>
    <collision>
      <geometry>
        <cylinder length="0.2" radius="0.06"/>
      </geometry>
    </collision>
    <inertial>
      <mass value="2"/>
      <inertia ixx="0.05" ixy="0" ixz="0" iyy="0.05" iyz="0" izz="0.05"/>
    </inertial>
  </link>

  <joint name="joint_4" type="revolute">
    <parent link="link_3"/>
    <child link="link_4"/>
    <origin xyz="0 0 0.2" rpy="1.57 0 0"/>
    <axis xyz="0 0 1"/>
    <limit lower="-2.09" upper="2.09" effort="150" velocity="1.7"/>
  </joint>

  <link name="link_5">
    <visual>
      <geometry>
        <cylinder length="0.15" radius="0.05"/>
      </geometry>
      <material name="orange">
        <color rgba="1 0.5 0 1"/>
      </material>
    </visual>
    <collision>
      <geometry>
        <cylinder length="0.15" radius="0.05"/>
      </geometry>
    </collision>
    <inertial>
      <mass value="1"/>
      <inertia ixx="0.02" ixy="0" ixz="0" iyy="0.02" iyz="0" izz="0.02"/>
    </inertial>
  </link>

  <joint name="joint_5" type="revolute">
    <parent link="link_4"/>
    <child link="link_5"/>
    <origin xyz="0 0 0.2" rpy="-1.57 0 0"/>
    <axis xyz="0 0 1"/>
    <limit lower="-2.97" upper="2.97" effort="150" velocity="1.7"/>
  </joint>

  <link name="link_6">
    <visual>
      <geometry>
        <cylinder length="0.1" radius="0.04"/>
      </geometry>
      <material name="orange">
        <color rgba="1 0.5 0 1"/>
      </material>
    </visual>
    <collision>
      <geometry>
        <cylinder length="0.1" radius="0.04"/>
      </geometry>
    </collision>
    <inertial>
      <mass value="0.5"/>
      <inertia ixx="0.01" ixy="0" ixz="0" iyy="0.01" iyz="0" izz="0.01"/>
    </inertial>
  </link>

  <joint name="joint_6" type="revolute">
    <parent link="link_5"/>
    <child link="link_6"/>
    <origin xyz="0 0 0.15" rpy="1.57 0 0"/>
    <axis xyz="0 0 1"/>
    <limit lower="-2.09" upper="2.09" effort="150" velocity="1.7"/>
  </joint>

  <link name="link_7">
    <visual>
      <geometry>
        <cylinder length="0.08" radius="0.03"/>
      </geometry>
      <material name="grey">
        <color rgba="0.3 0.3 0.3 1"/>
      </material>
    </visual>
    <collision>
      <geometry>
        <cylinder length="0.08" radius="0.03"/>
      </geometry>
    </collision>
    <inertial>
      <mass value="0.2"/>
      <inertia ixx="0.005" ixy="0" ixz="0" iyy="0.005" iyz="0" izz="0.005"/>
    </inertial>
  </link>

  <joint name="joint_7" type="revolute">
    <parent link="link_6"/>
    <child link="link_7"/>
    <origin xyz="0 0 0.1" rpy="-1.57 0 0"/>
    <axis xyz="0 0 1"/>
    <limit lower="-3.05" upper="3.05" effort="150" velocity="1.7"/>
  </joint>

  <!-- Simple gripper -->
  <link name="gripper_base">
    <visual>
      <geometry>
        <box size="0.05 0.05 0.02"/>
      </geometry>
      <material name="black">
        <color rgba="0 0 0 1"/>
      </material>
    </visual>
    <collision>
      <geometry>
        <box size="0.05 0.05 0.02"/>
      </geometry>
    </collision>
    <inertial>
      <mass value="0.1"/>
      <inertia ixx="0.001" ixy="0" ixz="0" iyy="0.001" iyz="0" izz="0.001"/>
    </inertial>
  </link>

  <joint name="gripper_joint" type="fixed">
    <parent link="link_7"/>
    <child link="gripper_base"/>
    <origin xyz="0 0 0.08" rpy="0 0 0"/>
  </joint>

  <link name="gripper_finger_1">
    <visual>
      <geometry>
        <box size="0.02 0.01 0.04"/>
      </geometry>
      <material name="black">
        <color rgba="0 0 0 1"/>
      </material>
    </visual>
    <collision>
      <geometry>
        <box size="0.02 0.01 0.04"/>
      </geometry>
    </collision>
    <inertial>
      <mass value="0.01"/>
      <inertia ixx="0.0001" ixy="0" ixz="0" iyy="0.0001" iyz="0" izz="0.0001"/>
    </inertial>
  </link>

  <joint name="gripper_finger_1_joint" type="prismatic">
    <parent link="gripper_base"/>
    <child link="gripper_finger_1"/>
    <origin xyz="0.02 0 0.01" rpy="0 0 0"/>
    <axis xyz="1 0 0"/>
    <limit lower="0" upper="0.04" effort="10" velocity="0.1"/>
  </joint>

  <link name="gripper_finger_2">
    <visual>
      <geometry>
        <box size="0.02 0.01 0.04"/>
      </geometry>
      <material name="black">
        <color rgba="0 0 0 1"/>
      </material>
    </visual>
    <collision>
      <geometry>
        <box size="0.02 0.01 0.04"/>
      </geometry>
    </collision>
    <inertial>
      <mass value="0.01"/>
      <inertia ixx="0.0001" ixy="0" ixz="0" iyy="0.0001" iyz="0" izz="0.0001"/>
    </inertial>
  </link>

  <joint name="gripper_finger_2_joint" type="prismatic">
    <parent link="gripper_base"/>
    <child link="gripper_finger_2"/>
    <origin xyz="-0.02 0 0.01" rpy="0 0 0"/>
    <axis xyz="1 0 0"/>
    <limit lower="-0.04" upper="0" effort="10" velocity="0.1"/>
  </joint>
</robot>